Workbook
Name BD_EESS: #REF!
Name Tabla_zonas: [1]Hoja4!$J$5:$N$111

Sheet Liquidación
A1: COTIZACIÓN DE SERVICIOS | G1: N° | H1: 56-01
B3: Servicio : | D3: N° de Solicitud: | G3: Categoria: | H3: II.EE. Baja Tensión
B4: RUC: | C4: 20539249640 | D4: Cliente: | E4: Piura - PVH | G4: CECO: | H4: =VLOOKUP(E4,'Lista de Tiendas'!A3:D200,3) -> 29150404
B5: Empresa : | C5: SAT INDUSTRIALES | D5: Jefe de Energía y SCI: | E5: Raul Quispe | G5: Fecha ejec:
B6: Cotizado Por: | C6: JOEL VIERA | D6: Fecha de cotización: | G6: Total: | H6: =+SUM(Liquidación!$H$9:$H$17) -> 0
C7: Solo digitar las columnas y celdas en celeste
A8: Item | B8: Línea | C8: Descripción de línea del preciario | D8: Comentario | E8: Unidad | F8: Cant. | G8: P.u | H8: Subtotal
A9: 1 | C9: VIATICOS
B10: VABT21 | C10: =+VLOOKUP(B10,'Preciario SAT BT'!$A$3:$D$1000,2,0) -> VIATICO CORRECTIVO DIA ADICIONAL (ALOJAMIENTO Y HOSPEDAJE) | E10: =+VLOOKUP(B10,'Preciario SAT BT'!$A$3:$D$1000,3,0) -> POR PERSONA X DIA | G10: =+VLOOKUP(B10,'Preciario SAT BT'!$A$3:$D$1000,4,0) -> 83 | H10: =+IFERROR(F10*G10,0) -> 0
C11: =+VLOOKUP(B11,'Preciario SAT BT'!$A$3:$D$1000,2,0) -> #N/A | E11: =+VLOOKUP(B11,'Preciario SAT BT'!$A$3:$D$1000,3,0) -> #N/A | G11: =+VLOOKUP(B11,'Preciario SAT BT'!$A$3:$D$1000,4,0) -> #N/A | H11: =+IFERROR(F11*G11,0) -> 0
A12: 2 | C12: SUMINISTRO
C13: =+VLOOKUP(B13,'Preciario SAT BT'!$A$3:$D$1000,2,0) -> #N/A | E13: =+VLOOKUP(B13,'Preciario SAT BT'!$A$3:$D$1000,3,0) -> #N/A | G13: =+VLOOKUP(B13,'Preciario SAT BT'!$A$3:$D$1000,4,0) -> #N/A | H13: =+IFERROR(F13*G13,0) -> 0
C14: =+VLOOKUP(B14,'Preciario SAT BT'!$A$3:$D$1000,2,0) -> #N/A | E14: =+VLOOKUP(B14,'Preciario SAT BT'!$A$3:$D$1000,3,0) -> #N/A | G14: =+VLOOKUP(B14,'Preciario SAT BT'!$A$3:$D$1000,4,0) -> #N/A | H14: =+IFERROR(F14*G14,0) -> 0
A15: 3 | C15: MANO DE OBRA
C16: =+VLOOKUP(B16,'Preciario SAT BT'!$A$3:$D$1000,2,0) -> #N/A | E16: =+VLOOKUP(B16,'Preciario SAT BT'!$A$3:$D$1000,3,0) -> #N/A | F16: 1 | G16: =+VLOOKUP(B16,'Preciario SAT BT'!$A$3:$D$1000,4,0) -> #N/A | H16: =+IFERROR(F16*G16,0) -> 0
C17: =+VLOOKUP(B17,'Preciario SAT BT'!$A$3:$D$1000,2,0) -> #N/A | E17: =+VLOOKUP(B17,'Preciario SAT BT'!$A$3:$D$1000,3,0) -> #N/A | F17: 1 | G17: =+VLOOKUP(B17,'Preciario SAT BT'!$A$3:$D$1000,4,0) -> #N/A | H17: =+IFERROR(F17*G17,0) -> 0

Sheet Preciario SAT BT
A1: PRECIARIO ADJUDICADO ENERGY: IIEE BAJA TENSIÓN
B2: Precios no incluyen IGV | C2: Esta hoja es inmodificable
A3: LÍNEA SAP | B3: DESCRIPCIÓN LINEA SAP DIAR INGENIEROS IIEE BT | C3: UNIDAD | D3: P.U.
B4: Mantenimiento Preventivo Baja Tensión
A5: MPBT01 | B5: MP TABLERO ADOSADO O EMPOTRADO | C5: UNIDAD | D5: 81.86
A6: MPBT02 | B6: MP TABLERO AUTOSOPORTADO | C6: UNIDAD | D6: 93
A7: MPBT03 | B7: MP POZO A TIERRA T_CONVENCIONAL BT | C7: UNIDAD | D7: 219.51
A8: MPBT04 | B8: MP POZO A TIERRA T_MALLA BT | C8: UNIDAD | D8: 219.51
A9: MPBT05 | B9: MP TABLERO BCO CONDENSADORES | C9: UNIDAD | D9: 221.89
A10: MPBT06 | B10: MP GENERADOR ESTATICO REACTIVOS | C10: UNIDAD | D10: 234.04
A11: MPBT07 | B11: MP FILTRO DE ARMONICOS | C11: UNIDAD | D11: 240.89
A12: MPBT08 | B12: SERV. MP VARIADORES | C12: UNIDAD | D12: 214.89
A13: MPBT09 | B13: PDR PREVENCIONISTA BT (HONORARIOS) | C13: POR VISITA / SEDE | D13: 165.76
A14: MPBT10 | B14: VIATICO DIA ADICIONAL RUTA (HOSPEDAJE Y ALIMENTACIÓN) | C14: POR RUTA X SEDE X DIA | D14: 117
A15: MPBT11 | B15: GESTION INVENTARIO ELEC TIENDA DE 0 A 10 EQUIPOS | C15: TIENDA | D15: 26.52
A16: MPBT12 | B16: GESTION INVENTARIO ELEC TIENDA DE 11 A 20 EQUIPOS | C16: TIENDA | D16: 26.52
... A25: MPBT21 | B25: GESTION INVENTARIO ELEC TIENDA DE MÁS DE 100 EQUIPOS | C25: TIENDA | D25: 41.25
A26: MPBT22 | B26: VIATICO LIMA ( CAÑETE, MALA) - ALIMENTACIÓN, HOSPEDAJE Y PASAJE I/V | C26: POR RUTA / DIA / SEDE | D26: NA
A27: MPBT23 | B27: VIATICO SUR CHICO ( ASIA) - ALIMENTACIÓN, HOSPEDAJE Y PASAJE I/V | C27: POR RUTA / DIA / SEDE | D27: NA
A28: MPBT24 | B28: VIATICO SUR ( AREQUIPA) - ALIMENTACIÓN, HOSPEDAJE Y PASAJE I/V | C28: POR RUTA / DIA / SEDE | D28: NA
A29: MPBT25 | B29: VIATICO SUR ( CUSCO) - ALIMENTACIÓN, HOSPEDAJE Y PASAJE I/V | C29: POR RUTA / DIA / SEDE | D29: NA
A30: MPBT26 | B30: VIATICO SUR ( ILO) - ALIMENTACIÓN, HOSPEDAJE Y PASAJE I/V | C30: POR RUTA / DIA / SEDE | D30: NA
A31: MPBT27 | B31: VIATICO SUR ( JULIACA) - ALIMENTACIÓN, HOSPEDAJE Y PASAJE I/V | C31: POR RUTA / DIA / SEDE | D31: NA
A32: MPBT28 | B32: VIATICO SUR ( MOQUEGUA) - ALIMENTACIÓN, HOSPEDAJE Y PASAJE I/V | C32: POR RUTA / DIA / SEDE | D32: NA
A33: MPBT29 | B33: VIATICO SUR ( PUNO) - ALIMENTACIÓN, HOSPEDAJE Y PASAJE I/V | C33: POR RUTA / DIA / SEDE | D33: NA
A34: MPBT30 | B34: VIATICO SUR ( TACNA) - ALIMENTACIÓN, HOSPEDAJE Y PASAJE I/V | C34: POR RUTA / DIA / SEDE | D34: NA
A35: MPBT31 | B35: VIATICO SUR CHICO ( CHINCHA) - ALIMENTACIÓN, HOSPEDAJE Y PASAJE I/V | C35: POR RUTA / DIA / SEDE | D35: NA
A36: MPBT32 | B36: VIATICO SUR CHICO ( ICA) - ALIMENTACIÓN, HOSPEDAJE Y PASAJE I/V | C36: POR RUTA / DIA / SEDE | D36: NA
A37: MPBT33 | B37: VIATICO SUR CHICO ( PISCO) - ALIMENTACIÓN, HOSPEDAJE Y PASAJE I/V | C37: POR RUTA / DIA / SEDE | D37: NA
A38: MPBT34 | B38: PDR PREVENCIONISTA BT (HONORARIOS) | C38: POR VISITA / SEDE | D38: 165.76
A39: MPBT35 | B39: VIATICO CENTRO ( HUANCAYO) - ALIMENTACIÓN, HOSPEDAJE Y PASAJE I/V | C39: POR RUTA X SEDE X DIA | D39: NA
A40: MPBT36 | B40: VIATICO NORTE ( CAJAMARCA) - ALIMENTACIÓN, HOSPEDAJE Y PASAJE I/V | C40: POR RUTA X SEDE X DIA | D40: 267.28
A41: MPBT37 | B41: VIATICO NORTE ( TRUJILLO) - ALIMENTACIÓN, HOSPEDAJE Y PASAJE I/V | C41: POR RUTA X SEDE X DIA | D41: 190
A42: MPBT38 | B42: VIATICO NORTE ( CHICLAYO) - ALIMENTACIÓN, HOSPEDAJE Y PASAJE I/V | C42: POR RUTA X SEDE X DIA | D42: 177.83
A43: MPBT39 | B43: VIATICO NORTE ( CHIMBOTE) - ALIMENTACIÓN, HOSPEDAJE Y PASAJE I/V | C43: POR RUTA X SEDE X DIA | D43: 202
A44: MPBT40 | B44: VIATICO NORTE ( PIURA) - ALIMENTACIÓN, HOSPEDAJE Y PASAJE I/V | C44: POR RUTA X SEDE X DIA | D44: 29
A45: MPBT41 | B45: VIATICO NORTE ( JAÉN) - ALIMENTACIÓN, HOSPEDAJE Y PASAJE I/V | C45: POR RUTA X SEDE X DIA | D45: 206.37
A46: MPBT42 | B46: VIATICO NORTE ( PAITA) - ALIMENTACIÓN, HOSPEDAJE Y PASAJE I/V | C46: POR RUTA X SEDE X DIA | D46: 34
A47: MPBT43 | B47: VIATICO NORTE ( SULLANA) - ALIMENTACIÓN, HOSPEDAJE Y PASAJE I/V | C47: POR RUTA X SEDE X DIA | D47: 34
A48: MPBT44 | B48: VIATICO NORTE ( TALARA) - ALIMENTACIÓN, HOSPEDAJE Y PASAJE I/V | C48: POR RUTA X SEDE X DIA | D48: 48
...

Sheet Lista de Tiendas
A2: TIENDA | B2: FORMATO | C2: CECO | D2: SOCIEDAD | G2: RUBRO | L2: FORMATO
A3: Jockey Plaza - PVH | B3: PVH | C3: 25102001 | D3: A125 | G3: Grupos electrógenos | L3: PVH
A4: Higuereta - PVH | B4: PVH | C4: 25102002 | D4: A125 | G4: II.EE. Baja Tensión | L4: PVO
A5: Brasil - PVH | B5: PVH | C5: 25102004 | D5: A125 | G5: II.EE. Media Tensión | L5: PVS
A6: Cortijo - PVH | B6: PVH | C6: 25102005 | D6: A125 | G6: UPS | L6: PVE
A7: Callao - PVH | B7: PVH | C7: 25102006 | D7: A125 | G7: Sistema Contraincendios | L7: VV
A8: Ate - PVH | B8: PVH | C8: 25102008 | D8: A125 | G8: Extintores | L8: MK
A9: Bolichera - PVH | B9: PVH | C9: 25102009 | D9: A125 | G9: Puertas cortafuegos | L9: JKR
A10: Risso - PVH | B10: PVH | C10: 25102011 | D10: A125 | L10: ALM.
A11: Los Olivos - PVH | B11: PVH | C11: 25102013 | D11: A125 | L11: OFIC.
A12: Comas - PVH | B12: PVH | C12: 25102014 | D12: A125
A13: Trujillo - PVH | B13: PVH | C13: 25102017 | D13: A125
A14: Chiclayo - PVH | B14: PVH | C14: 25102018 | D14: A125
A15: Arequipa - PVH | B15: PVH | C15: 25102019 | D15: A125
A16: Ceres - PVH | B16: PVH | C16: 25102020 | D16: A125
A17: Pro - PVH | B17: PVH | C17: 25102021 | D17: A125
A18: Huancayo - PVH | B18: PVH | C18: 25102022 | D18: A125
A19: Izaguirre - PVH | B19: PVH | C19: 25102023 | D19: A125
A20: Alfonso Ugarte - PVH | B20: PVH | C20: 25102024 | D20: A125
A21: Universitaria - PVH | B21: PVH | C21: 25102025 | D21: A125
A22: Puente Piedra - PVH | B22: PVH | C22: 25102026 | D22: A125
A23: SJ Lurigancho - PVH | B23: PVH | C23: 25102030 | D23: A125
... A148: SMP - MK | B148: MK | C148: 24107042 | D148: A124
A149: SJM - MK | B149: MK | D149: A124
A150: HO (Oficina Central) - MK
A151: Cusco - MK (Centro Comercial)
A154: HUB 001 Miraflores | B154: JKR | D154: A128
A155: HUB 002 Surco / Jorge Chavez | B155: JKR | D155: A128
A156: HUB 004 Lince | B156: JKR | D156: A128
A157: HUB 005 Surco / Benavides | B157: JKR | D157: A128
A158: HUB 006 Pueblo Libre | B158: JKR | D158: A128
A159: HUB 007 Surco / Primavera | B159: JKR | D159: A128
A160: HUB 009 San Luis | B160: JKR | D160: A128
A161: HUB 011 Punta Hermosa | B161: JKR | D161: A128
A162: HUB 013 Surquillo | B162: JKR | D162: A128
A165: Alm. Santa Rosa | B165: ALM. | C165: 29150404
A166: Oficinas Morelli | B166: OFIC. | C166: 29150404 | D166: A129

Sheet Inf. Cierre SAP C.M
B2: INFORME DE CIERRE CONTABLE COORDINADOR DE MANTENIMIENTO
G3: =SUM('Inf. Cierre SAP C.M'!$G$5:$G$29) -> 0
B4: N° Orden Mantto | C4: N° Solicitud | D4: N° Solped | E4: N° Pedido | F4: N° MIGO | G4: Subtotal S/.
